<?xml version="1.0" encoding="utf-8"?>
<robot name="gsim_urdf_pkg">

    <!-- Static link connecting world to base_link -->
    <link name="world"/>
    <joint name="base_to_world" type="fixed">
        <origin xyz="0 0 0" rpy="0 0 0"/>
        <parent link="world"/>
        <child link="base_link"/>
    </joint>

    <!-- Base link for shaking table -->
    <link name="base_link">
        <inertial>
            <origin xyz="0 0 0.025" rpy="0 0 0"/>
            <mass value="6.125"/>
            <inertia ixx="0.063802" iyy="0.063802" izz="0.12505" ixy="0" ixz="0" iyz="0"/>
        </inertial>
        <visual>
            <origin xyz="0 0 0" rpy="0 0 0"/>
            <geometry>
                <mesh filename="package://gsim_urdf_pkg/meshes/base_link.STL"/>
            </geometry>
            <material name="">
                <color rgba="0.79216 0.81961 0.93333 1"/>
            </material>
        </visual>
        <collision>
            <origin xyz="0 0 0" rpy="0 0 0"/>
            <geometry>
                <mesh filename="package://gsim_urdf_pkg/meshes/base_link.STL"/>
            </geometry>
        </collision>
    </link>

    <!-- Shaking table plugin -->
    <gazebo>
        <plugin name="shaking_table_plugin" filename="libshaking_table_plugin.so">
            <amplitude>0.001</amplitude> <!-- Amplitude in meters -->
            <frequency_min>1.0</frequency_min> <!-- Minimum frequency in Hz -->
            <frequency_max>30.0</frequency_max> <!-- Maximum frequency in Hz -->
            <sweep_rate>0.05</sweep_rate> <!-- Rate of frequency increase in Hz/s -->
            <motion_axis>y</motion_axis> <!-- Axis of motion: x, y, or z -->
            <phase_offset>0.0</phase_offset> <!-- Phase shift in radians -->
            <damping_factor>0.05</damping_factor> <!-- Damping factor -->
        </plugin>
    </gazebo>

    <gazebo reference="camera_link">
        <sensor name="camera" type="camera">
            <pose>0 0 5 0 0 0</pose>
            <camera>
            <!-- <horizontal_fov>1.5708</horizontal_fov> -->
            <horizontal_fov>2.5</horizontal_fov>
            <image>
                <width>1920</width>
                <height>1080</height>
                <format>R8G8B8</format>
            </image>
            <clip>
                <near>0.1</near>
                <far>1000</far>
            </clip>
            </camera>
            <update_rate>60</update_rate>
            <plugin name="camera_controller" filename="libgazebo_ros_camera.so">
            <alwaysOn>true</alwaysOn>
            <updateRate>60.0</updateRate>
            <cameraName>camera</cameraName>
            <imageTopicName>image_raw</imageTopicName>
            <cameraInfoTopicName>camera_info</cameraInfoTopicName>
            <frameName>camera_link</frameName>
            </plugin>
        </sensor>
    </gazebo>


    <!-- Floor 1 -->
    <link name="first_link">
        <inertial>
            <origin xyz="0.06 0.073 0.175" rpy="0 0 0"/>
            <mass value="5.2657"/>
            <inertia ixx="0.012714" iyy="0.0098435" izz="0.015733" ixy="0" ixz="0" iyz="0"/>
        </inertial>
        <visual>
            <origin xyz="0 0 0" rpy="0 0 0"/>
            <geometry>
                <mesh filename="package://gsim_urdf_pkg/meshes/first_link.STL"/>
            </geometry>
            <material name="">
                <color rgba="0.75294 0.75294 0.75294 1"/>
            </material>
        </visual>
        <collision>
            <origin xyz="0 0 0" rpy="0 0 0"/>
            <geometry>
                <mesh filename="package://gsim_urdf_pkg/meshes/first_link.STL"/>
            </geometry>
        </collision>
    </link>
    <joint name="Joint_First" type="prismatic">
        <origin xyz="-0.05 -0.08 0.05" rpy="0 0 0"/>
        <parent link="base_link"/>
        <child link="first_link"/>
        <axis xyz="0 1 0"/>
        <limit lower="-0.01" upper="0.01" effort="5" velocity="0.5"/>
        <dynamics damping="0.1" friction="0.5"/>
    </joint>

    <!-- Floor 2 -->
    <link name="second_link">
        <inertial>
            <origin xyz="0.06 0.075 0.175" rpy="0 0 0"/>
            <mass value="5.2657"/>
            <inertia ixx="0.012714" iyy="0.0098435" izz="0.015733" ixy="0" ixz="0" iyz="0"/>
        </inertial>
        <visual>
            <origin xyz="0 0 0" rpy="0 0 0"/>
            <geometry>
                <mesh filename="package://gsim_urdf_pkg/meshes/second_link.STL"/>
            </geometry>
            <material name="">
                <color rgba="0.75294 0.75294 0.75294 1"/>
            </material>
        </visual>
        <collision>
            <origin xyz="0 0 0" rpy="0 0 0"/>
            <geometry>
                <mesh filename="package://gsim_urdf_pkg/meshes/second_link.STL"/>
            </geometry>
        </collision>
    </link>
    <joint name="Joint_Second" type="prismatic">
        <origin xyz="0 -0.002 0.35" rpy="0 0 0"/>
        <parent link="first_link"/>
        <child link="second_link"/>
        <axis xyz="0 1 0"/>
        <limit lower="-0.01" upper="0.01" effort="5" velocity="0.5"/>
        <dynamics damping="0.1" friction="0.5"/>
    </joint>

    <!-- Floor 3 -->
    <link name="third_link">
        <inertial>
            <origin xyz="0.06 0.075 0.175" rpy="0 0 0"/>
            <mass value="5.2657"/>
            <inertia ixx="0.012714" iyy="0.0098435" izz="0.015733" ixy="0" ixz="0" iyz="0"/>
        </inertial>
        <visual>
            <origin xyz="0 0 0" rpy="0 0 0"/>
            <geometry>
                <mesh filename="package://gsim_urdf_pkg/meshes/third_link.STL"/>
            </geometry>
            <material name="">
                <color rgba="0.75294 0.75294 0.75294 1"/>
            </material>
        </visual>
        <collision>
            <origin xyz="0 0 0" rpy="0 0 0"/>
            <geometry>
                <mesh filename="package://gsim_urdf_pkg/meshes/third_link.STL"/>
            </geometry>
        </collision>
    </link>
    <joint name="Joint_Third" type="prismatic">
        <origin xyz="0 0 0.35" rpy="0 0 0"/>
        <parent link="second_link"/>
        <child link="third_link"/>
        <axis xyz="0 1 0"/>
        <limit lower="-0.01" upper="0.01" effort="5" velocity="0.5"/>
        <dynamics damping="0.1" friction="0.5"/>
    </joint>

    <!-- Floor 4 -->
    <link name="fourth_link">
        <inertial>
            <origin xyz="0.06 0.074 0.175" rpy="0 0 0"/>
            <mass value="5.2657"/>
            <inertia ixx="0.012714" iyy="0.0098435" izz="0.015733" ixy="0" ixz="0" iyz="0"/>
        </inertial>
        <visual>
            <origin xyz="0 0 0" rpy="0 0 0"/>
            <geometry>
                <mesh filename="package://gsim_urdf_pkg/meshes/fourth_link.STL"/>
            </geometry>
            <material name="">
                <color rgba="0.75294 0.75294 0.75294 1"/>
            </material>
        </visual>
        <collision>
            <origin xyz="0 0 0" rpy="0 0 0"/>
            <geometry>
                <mesh filename="package://gsim_urdf_pkg/meshes/fourth_link.STL"/>
            </geometry>
        </collision>
    </link>
    <joint name="Joint_Fourth" type="prismatic">
        <origin xyz="0 0.001 0.35" rpy="0 0 0"/>
        <parent link="third_link"/>
        <child link="fourth_link"/>
        <axis xyz="0 1 0"/>
        <limit lower="-0.01" upper="0.01" effort="5" velocity="0.5"/>
        <dynamics damping="0.1" friction="0.5"/>
    </joint>

    <!-- Floor 5 -->
    <link name="fifth_link">
        <inertial>
            <origin xyz="0.06 0.075 0.175" rpy="0 0 0"/>
            <mass value="5.2657"/>
            <inertia ixx="0.012714" iyy="0.0098435" izz="0.015733" ixy="0" ixz="0" iyz="0"/>
        </inertial>
        <visual>
            <origin xyz="0 0 0" rpy="0 0 0"/>
            <geometry>
                <mesh filename="package://gsim_urdf_pkg/meshes/fifth_link.STL"/>
            </geometry>
            <material name="">
                <color rgba="0.75294 0.75294 0.75294 1"/>
            </material>
        </visual>
        <collision>
            <origin xyz="0 0 0" rpy="0 0 0"/>
            <geometry>
                <mesh filename="package://gsim_urdf_pkg/meshes/fifth_link.STL"/>
            </geometry>
        </collision>
    </link>
    <joint name="Joint_Fifth" type="prismatic">
        <origin xyz="0 -0.001 0.35" rpy="0 0 0"/>
        <parent link="fourth_link"/>
        <child link="fifth_link"/>
        <axis xyz="0 1 0"/>
        <limit lower="-0.01" upper="0.01" effort="5" velocity="0.5"/>
        <dynamics damping="0.1" friction="0.5"/>
    </joint>

    <!-- Camera Sensor -->
    <link name="camera_link">
        <inertial>
            <origin xyz="0 0 0" rpy="0 0 0"/>
            <mass value="0.1"/>
            <inertia ixx="0.0001" iyy="0.0001" izz="0.0001" ixy="0" ixz="0" iyz="0"/>
        </inertial>
        <visual>
            <origin xyz="0 0 0" rpy="0 0 0"/>
            <geometry>
                <box size="0.1 0.1 0.1"/>
            </geometry>
            <material name="">
                <color rgba="0.75294 0.75294 0.75294 1"/>
            </material>
        </visual>
        <collision>
            <origin xyz="0 0 0" rpy="0 0 0"/>
            <geometry>
                <box size="0.1 0.1 0.1"/>
            </geometry>
        </collision>
    </link>
    <joint name="camera_joint" type="fixed">
        <origin xyz="-1 0 1" rpy="0 0 0"/>
        <parent link="base_link"/>
        <child link="camera_link"/>
    </joint>

    <!-- Apriltag  -->
    <!-- AprilTag Reference -->
    <gazebo reference="fifth_link">
        <model name="apriltag">
            <pose>0 0 0.35 0 0 0</pose> <!-- Adjust position relative to fifth_link -->
            <file>model://Apriltag36_11_00000</file>
        </model>
    </gazebo>
</robot>
